<?xml version="1.0" ?> 
<robot name="rrbot">
  <material name="black">
    <color rgba="0 0 0 1" />
  </material>

  <material name="blue">
    <color rgba="0 0 1 1" />
  </material>

  <material name="green">
    <color rgba="0 1 0 1" />
  </material>

  <material name="white">
    <color rgba="1 1 1 1" />
  </material>

  <material name="yellow">
    <color rgba="1 1 0 1" />
  </material>

  <link name="base" >
    <visual>
      <geometry>
        <box size="0.5 0.5 2" />
      </geometry>
      <material name="black" />
    </visual>
    <inertial>
      <mass value="50" />
      <inertia ixx="225" ixy="0" ixz="0"
              iyy="225" iyz="0"
              izz="200" />
    </inertial>
    <collision>
      <geometry>
        <box size="0.1 0.1 2" />
      </geometry>
      <contact_coefficients mu="0" kp="1000" kd="1" />
    </collision>
  </link>

  <link name="arm_base" >
    <visual>
      <geometry>
        <box size="0.4 0.2 0.2" />
      </geometry>
      <material name="blue" />
      <origin xyz="-0.4 0 0" rpy="0 0 0" />
    </visual>
    <inertial>
      <mass value="2.0" />
        <inertia ixx="15" ixy="0" ixz="0"
                  iyy="20" iyz="0"
                  izz="15" />
    </inertial>
    <collision>
      <geometry>
        <box size="0.4 0.2 0.2" />
      </geometry>
      <origin xyz="-0.4 0 0" rpy="0 0 0" />
      <contact_coefficients mu="0" kp="1000" kd="1" />
    </collision>
  </link>

  <link name="lower_arm" >
    <visual>
      <geometry>
        <box size="0.6 0.2 0.2" />
      </geometry>
      <material name="yellow" />
      <origin xyz="-0.25 0 0" rpy="0 0 0" />
    </visual>
    <inertial>
      <mass value="1" />
        <inertia ixx="6.7" ixy="0" ixz="0"
                  iyy="10" iyz="0"
                  izz="6.7" />
    </inertial>
    <collision> 
      <geometry>
        <box size="0.6 0.2 0.2" />
      </geometry>
      <origin xyz="-0.25 0 0" rpy="0 0 0" />
      <contact_coefficients mu="0" kp="1000" kd="1" />
    </collision>
  </link>

  <link name="hand_base" >
    <visual>
      <geometry>
        <cylinder length="0.05" radius="0.1" />
      </geometry>
      <material name="green" />
      <origin xyz="0 0 0" rpy="0 1.57075 0" />
    </visual>
    <inertial>
      <mass value="0.2" />
        <inertia ixx="4.6" ixy="0" ixz="0"
                  iyy="1.274" iyz="0"
                  izz="4.6" />
    </inertial>
    <collision>
      <geometry>
        <cylinder length="0.05" radius="0.1" />
      </geometry>
      <origin xyz="0 0 0" rpy="0 1.57075 0" />
      <contact_coefficients mu="0" kp="1000" kd="1" />
    </collision>
  </link>

  <link name="up_hand" >
    <visual>
      <geometry>
        <box size="0.1 0.02 0.02" />
      </geometry>
      <material name="white" />
      <origin xyz="-0.08 0 0" rpy="0 -1.57075 0" />
    </visual>
    <inertial>
      <mass value="0.01" />
        <inertia ixx="0.6" ixy="0" ixz="0"
                  iyy="0.2" iyz="0"
                  izz="0.6" />
    </inertial>
    <collision>
      <geometry>
        <box size="0.1 0.02 0.02" />
      </geometry>
      <origin xyz="-0.08 0 0" rpy="0 -1.57075 0" />
      <contact_coefficients mu="0" kp="1000" kd="1" />
    </collision>
  </link>

  <link name="down_hand" >
    <visual>
      <geometry>
        <box size="0.1 0.02 0.02" />
      </geometry>
      <material name="white" />
      <origin xyz="-0.08 0 0" rpy="0 1.57075 0" />
    </visual>
    <inertial>
      <mass value="0.01" />
        <inertia ixx="0.6" ixy="0" ixz="0"
                  iyy="0.2" iyz="0"
                  izz="0.6" />
    </inertial>
    <collision>
      <geometry>
        <box size="0.1 0.02 0.02" />
      </geometry>
      <origin xyz="-0.08 0 0" rpy="0 1.57075 0" />
      <contact_coefficients mu="0" kp="1000" kd="1" />
    </collision>
  </link>

  <joint name="base_arm_base" type="continuous">
    <parent link="base" />
    <child link="arm_base" />
    <dynamics damping="0.1" friction="0.1" />
  </joint>

  <joint name="lower_lower" type="revolute">
    <parent link="arm_base" />
    <child link="lower_arm" />
    <origin xyz="-0.55 0 0.2" rpy="0 0 0" />
    <axis xyz="0 0 1" />
    <limit effort="100" lower="-2.3" upper="2.3" velocity="0.1" />
    <dynamics damping="0.1" friction="0.1" />
  </joint>

  <joint name="hand_base_to_lower_arm" type="continuous">
    <parent link="lower_arm" />
    <child link="hand_base" />
    <origin xyz="-0.55 0 0" rpy="0 0 0" />
    <dynamics damping="0.1" friction="0.1" />
  </joint>

  <joint name="up_hand_to_hand_base" type="prismatic">
    <parent link="hand_base" />
    <child link="up_hand" />
    <origin xyz="-0.08 0 0" rpy="0 1.57075 0" />
    <limit effort="1000" lower="0" upper="0.065" velocity="0.05" />
    <dynamics damping="0.1" friction="0.1" />
  </joint>

  <joint name="down_hand_to_hand_base" type="prismatic">
    <parent link="hand_base" />
    <child link="down_hand" />
    <origin xyz="-0.08 0 -0.1" rpy="0 1.57075 0" />
    <limit effort="1000" lower="0.065" upper="0" velocity="0.05" />
    <dynamics damping="0.1" friction="0.1" />
  </joint>
  
</robot>